Workbook

Sheet Raw Data
A1: ticker | B1: name | C1: currency | D1: exchange | E1: industry | F1: logo | G1: weburl | H1: environment_grade | I1: environment_level | J1: social_grade | K1: social_level | L1: governance_grade | M1: governance_level | N1: environment_score | O1: social_score | P1: governance_score | Q1: total_score | R1: last_processing_date | S1: total_grade | T1: total_level | U1: cik
A2: dis | B2: Walt Disney Co | C2: USD | D2: NEW YORK STOCK EXCHANGE, INC. | E2: Media | F2: https://static.finnhub.io/logo/ef50b4a2b263c847211b567a01edb702cae8b9ef46ca1f6856ca4432a70e9f52.png | G2: https://thewaltdisneycompany.com/ | H2: A | I2: High | J2: BB | K2: Medium | L2: BB | M2: Medium | N2: 510 | O2: 316 | P2: 321 | Q2: 1147 | R2: 44670 | S2: BBB | T2: High | U2: 1744489
A3: gm | B3: General Motors Co | C3: USD | D3: NEW YORK STOCK EXCHANGE, INC. | E3: Automobiles | F3: https://static.finnhub.io/logo/9253db78-80c9-11ea-920d-00000000092a.png | G3: https://www.gm.com/ | H3: A | I3: High | J3: BB | K3: Medium | L3: B | M3: Medium | N3: 510 | O3: 303 | P3: 255 | Q3: 1068 | R3: 44668 | S3: BBB | T3: High | U3: 1467858
A4: gww | B4: WW Grainger Inc | C4: USD | D4: NEW YORK STOCK EXCHANGE, INC. | E4: Trading Companies and Distributors | F4: https://static.finnhub.io/logo/f153dcda-80eb-11ea-bc2e-00000000092a.png | G4: https://www.grainger.com/ | H4: B | I4: Medium | J4: BB | K4: Medium | L4: B | M4: Medium | N4: 255 | O4: 385 | P4: 240 | Q4: 880 | R4: 44670 | S4: BB | T4: Medium | U4: 277135
A5: mhk | B5: Mohawk Industries Inc | C5: USD | D5: NEW YORK STOCK EXCHANGE, INC. | E5: Consumer products | F5: https://static.finnhub.io/logo/26868a62-80ec-11ea-9712-00000000092a.png | G5: https://mohawkind.com/ | H5: A | I5: High | J5: B | K5: Medium | L5: BB | M5: Medium | N5: 570 | O5: 298 | P5: 303 | Q5: 1171 | R5: 44669 | S5: BBB | T5: High | U5: 851968
A6: lyv | B6: Live Nation Entertainment Inc | C6: USD | D6: NEW YORK STOCK EXCHANGE, INC. | E6: Media | F6: https://static.finnhub.io/logo/1cd144d2-80ec-11ea-b50a-00000000092a.png | G6: https://www.livenationentertainment.com/ | H6: BBB | I6: High | J6: BB | K6: Medium | L6: B | M6: Medium | N6: 492 | O6: 310 | P6: 250 | Q6: 1052 | R6: 44669 | S6: BBB | T6: High | U6: 1335258
A7: lvs | B7: Las Vegas Sands Corp | C7: USD | D7: NEW YORK STOCK EXCHANGE, INC. | E7: Hotels Restaurants and Leisure | F7: https://static.finnhub.io/logo/7256a9be-8279-11ea-874d-00000000092a.png | G7: https://www.sands.com/ | H7: A | I7: High | J7: BB | K7: Medium | L7: BB | M7: Medium | N7: 547 | O7: 318 | P7: 313 | Q7: 1178 | R7: 44669 | S7: BBB | T7: High | U7: 1300514
A8: clx | B8: Clorox Co | C8: USD | D8: NEW YORK STOCK EXCHANGE, INC. | E8: Consumer products | F8: https://static.finnhub.io/logo/a67c34fe-80eb-11ea-a87f-00000000092a.png | G8: https://www.thecloroxcompany.com/ | H8: A | I8: High | J8: BB | K8: Medium | L8: BB | M8: Medium | N8: 560 | O8: 350 | P8: 345 | Q8: 1255 | R8: 44667 | S8: A | T8: High | U8: 21076
A9: aacg | B9: ATA Creativity Global | C9: CNY | D9: NASDAQ NMS - GLOBAL MARKET | E9: Diversified Consumer Services | F9: https://static2.finnhub.io/file/publicdatany/finnhubimage/stock_logo/AACG.svg | G9: http://www.ata.net.cn | H9: B | I9: Medium | J9: B | K9: Medium | L9: B | M9: Medium | N9: 203 | O9: 200 | P9: 205 | Q9: 608 | R9: 44743 | S9: B | T9: Medium | U9: 1420529
A10: aal | B10: American Airlines Group Inc | C10: USD | D10: NASDAQ NMS - GLOBAL MARKET | E10: Airlines | F10: https://static2.finnhub.io/file/publicdatany/finnhubimage/stock_logo/AAL.png | G10: https://americanairlines.gcs-web.com/ | H10: B | I10: Medium | J10: B | K10: Medium | L10: B | M10: Medium | N10: 270 | O10: 211 | P10: 265 | Q10: 746 | R10: 44667 | S10: B | T10: Medium | U10: 6201
A11: aame | B11: Atlantic American Corp | C11: USD | D11: NASDAQ NMS - GLOBAL MARKET | E11: Insurance | F11: https://static.finnhub.io/logo/6b536b3e-826a-11ea-bc66-00000000092a.png | G11: http://www.atlam.com/ | H11: B | I11: Medium | J11: B | K11: Medium | L11: BB | M11: Medium | N11: 220 | O11: 221 | P11: 300 | Q11: 741 | R11: 44667 | S11: B | T11: Medium | U11: 8177
A12: aaoi | B12: Applied Optoelectronics Inc | C12: USD | D12: NASDAQ NMS - GLOBAL MARKET | E12: Communications | F12: https://static.finnhub.io/logo/7afdb95a-80ce-11ea-849c-00000000092a.png | G12: http://ao-inc.com/ | H12: BB | I12: Medium | J12: B | K12: Medium | L12: B | M12: Medium | N12: 311 | O12: 256 | P12: 218 | Q12: 785 | R12: 44667 | S12: BB | T12: Medium | U12: 1158114
A13: aaon | B13: Aaon Inc | C13: USD | D13: NASDAQ NMS - GLOBAL MARKET | E13: Building | F13: https://static.finnhub.io/logo/8819421c-80df-11ea-80b9-00000000092a.png | G13: https://www.aaon.com/ | H13: A | I13: High | J13: BB | K13: Medium | L13: B | M13: Medium | N13: 500 | O13: 300 | P13: 223 | Q13: 1023 | R13: 44667 | S13: BBB | T13: High | U13: 824142
A14: aapl | B14: Apple Inc | C14: USD | D14: NASDAQ NMS - GLOBAL MARKET | E14: Technology | F14: https://static.finnhub.io/logo/87cb30d8-80df-11ea-8951-00000000092a.png | G14: https://www.apple.com/ | H14: BB | I14: Medium | J14: B | K14: Medium | L14: B | M14: Medium | N14: 355 | O14: 281 | P14: 255 | Q14: 891 | R14: 44667 | S14: BB | T14: Medium | U14: 320193
A15: aatc | B15: Autoscope Technologies Corp | C15: USD | D15: NASDAQ NMS - GLOBAL MARKET | E15: Electrical Equipment | H15: BBB | I15: High | J15: B | K15: Medium | L15: B | M15: Medium | N15: 410 | O15: 286 | P15: 240 | Q15: 936 | R15: 44723 | S15: BBB | T15: High | U15: 943034
A16: aaww | B16: Atlas Air Worldwide Holdings Inc | C16: USD | D16: NASDAQ NMS - GLOBAL MARKET | E16: Logistics and Transportation | F16: https://static.finnhub.io/logo/8b74bf8a-80df-11ea-8463-00000000092a.png | G16: https://www.atlasairworldwide.com/ | H16: A | I16: High | J16: B | K16: Medium | L16: B | M16: Medium | N16: 520 | O16: 243 | P16: 237 | Q16: 1000 | R16: 44667 | S16: BBB | T16: High | U16: 1135185
A17: aaci | B17: Armada Acquisition Corp I | C17: USD | D17: NASDAQ NMS - GLOBAL MARKET | E17: N/A | H17: B | I17: Medium | J17: B | K17: Medium | L17: B | M17: Medium | N17: 205 | O17: 200 | P17: 200 | Q17: 605 | R17: 44732 | S17: B | T17: Medium | U17: 1844817
A18: aadi | B18: Aadi Bioscience Inc | C18: USD | D18: NASDAQ NMS - GLOBAL MARKET | E18: Biotechnology | F18: https://static.finnhub.io/logo/358b0921e9d761a529cffa812e99b140f4bb9c2e1e63bfeee3a4ea7165257e7b.png | G18: https://aadibio.com/ | H18: B | I18: Medium | J18: B | K18: Medium | L18: B | M18: Medium | N18: 200 | O18: 201 | P18: 203 | Q18: 604 | R18: 44723 | S18: B | T18: Medium | U18: 1422142
A19: abeo | B19: Abeona Therapeutics Inc | C19: USD | D19: NASDAQ NMS - GLOBAL MARKET | E19: Biotechnology | F19: https://static.finnhub.io/logo/33b2a5a8-80d1-11ea-8de8-00000000092a.png | G19: https://abeonatherapeutics.com/ | H19: B | I19: Medium | J19: BB | K19: Medium | L19: BB | M19: Medium | N19: 205 | O19: 306 | P19: 310 | Q19: 821 | R19: 44667 | S19: BB | T19: Medium | U19: 318306
A20: abnb | B20: Airbnb Inc | C20: USD | D20: NASDAQ NMS - GLOBAL MARKET | E20: Hotels Restaurants and Leisure | F20: https://static2.finnhub.io/file/publicdatany/finnhubimage/stock_logo/ABNB.png | G20: https://www.airbnb.co.in/ | H20: A | I20: High | J20: A | K20: High | L20: BBB | M20: High | N20: 505 | O20: 570 | P20: 400 | Q20: 1475 | R20: 44722 | S20: A | T20: High | U20: 1559720
A21: abio | B21: ARCA Biopharma Inc | C21: USD | D21: NASDAQ NMS - GLOBAL MARKET | E21: Biotechnology | F21: https://static.finnhub.io/logo/52ec4c2e0c249a506cbce41ef284e287901cccb0a08db285aa9a9d4091ba8434.png | G21: http://arcabio.com/ | H21: B | I21: Medium | J21: B | K21: Medium | L21: B | M21: Medium | N21: 200 | O21: 222 | P21: 290 | Q21: 712 | R21: 44667 | S21: B | T21: Medium | U21: 907654
A22: abmd | B22: ABIOMED Inc | C22: USD | D22: NASDAQ NMS - GLOBAL MARKET | E22: Health Care | F22: https://static.finnhub.io/logo/8b2cc7cc-80df-11ea-b8c7-00000000092a.png | G22: https://www.abiomed.com/ | H22: A | I22: High | J22: BB | K22: Medium | L22: BB | M22: Medium | N22: 500 | O22: 324 | P22: 305 | Q22: 1129 | R22: 44667 | S22: BBB | T22: High | U22: 815094
A23: abos | B23: Acumen Pharmaceuticals Inc | C23: USD | D23: NASDAQ NMS - GLOBAL MARKET | E23: Biotechnology | F23: https://static.finnhub.io/logo/f1081a3d8031ad222b050bbbcfef7a073cea50638ad028f1fd31c5ca934f3820.png | G23: https://acumenpharm.com/ | H23: B | I23: Medium | J23: B | K23: Medium | L23: B | M23: Medium | N23: 205 | O23: 201 | P23: 200 | Q23: 606 | R23: 44723 | S23: B | T23: Medium | U23: 1576885
A24: absi | B24: Absci Corp | C24: USD | D24: NASDAQ NMS - GLOBAL MARKET | E24: Life Sciences Tools and Services | F24: https://static.finnhub.io/logo/d030f309b5a348085ba6297eadf507c1d7410dbf605e6147f34eec997f6f073f.png | G24: https://www.absci.com/ | H24: B | I24: Medium | J24: B | K24: Medium | L24: B | M24: Medium | N24: 205 | O24: 224 | P24: 230 | Q24: 659 | R24: 44723 | S24: B | T24: Medium | U24: 1672688
A25: abtx | B25: Allegiance Bancshares Inc | C25: USD | D25: NASDAQ NMS - GLOBAL MARKET | E25: Banking | F25: https://static.finnhub.io/logo/b34c7c52-80d2-11ea-8e19-00000000092a.png | G25: https://ir.allegiancebank.com/ | H25: B | I25: Medium | J25: BB | K25: Medium | L25: BB | M25: Medium | N25: 298 | O25: 300 | P25: 300 | Q25: 898 | R25: 44667 | S25: BB | T25: Medium | U25: 1642081
A26: abus | B26: Arbutus Biopharma Corp | C26: USD | D26: NASDAQ NMS - GLOBAL MARKET | E26: Biotechnology | F26: https://static.finnhub.io/logo/0068df02-80ca-11ea-abb6-00000000092a.png | G26: https://www.arbutusbio.com/ | H26: B | I26: Medium | J26: B | K26: Medium | L26: BB | M26: Medium | N26: 203 | O26: 204 | P26: 338 | Q26: 745 | R26: 44667 | S26: B | T26: Medium | U26: 1447028
A27: abvc | B27: ABVC Biopharma Inc | C27: USD | D27: NASDAQ NMS - GLOBAL MARKET | E27: Biotechnology | F27: https://static.finnhub.io/logo/2b1c9fbcfafa70dcfa10247ad6ebe12858ca5878a4c90e32840a2080a507eb3d.png | G27: https://abvcpharma.com/ | H27: B | I27: Medium | J27: B | K27: Medium | L27: B | M27: Medium | N27: 220 | O27: 212 | P27: 205 | Q27: 637 | R27: 44723 | S27: B | T27: Medium | U27: 1173313
A28: acad | B28: ACADIA Pharmaceuticals Inc | C28: USD | D28: NASDAQ NMS - GLOBAL MARKET | E28: Biotechnology | F28: https://static.finnhub.io/logo/2d87da57d47f7a5c0225c54f67d806d3a906cec1ea63d739dad084772cf5079c.png | G28: https://acadia.com/ | H28: B | I28: Medium | J28: B | K28: Medium | L28: BB | M28: Medium | N28: 230 | O28: 230 | P28: 305 | Q28: 765 | R28: 44667 | S28: BB | T28: Medium | U28: 1070494
A29: acac | B29: Acri Capital Acquisition Corp | C29: USD | D29: NASDAQ NMS - GLOBAL MARKET | E29: N/A | H29: B | I29: Medium | J29: B | K29: Medium | L29: BB | M29: Medium | N29: 200 | O29: 205 | P29: 300 | Q29: 705 | R29: 44722 | S29: B | T29: Medium | U29: 1914023
A30: accd | B30: Accolade Inc | C30: USD | D30: NASDAQ NMS - GLOBAL MARKET | E30: Health Care | F30: https://static.finnhub.io/logo/a967c80c75f9c72bb31fd3ae796a0a4e1e0dec7378ade4f78c06f10d89acf8bf.png | G30: https://www.accolade.com | H30: B | I30: Medium | J30: B | K30: Medium | L30: B | M30: Medium | N30: 255 | O30: 254 | P30: 235 | Q30: 744 | R30: 44722 | S30: B | T30: Medium | U30: 1481646
A31: acet | B31: Adicet Bio Inc | C31: USD | D31: NASDAQ NMS - GLOBAL MARKET | E31: Biotechnology | F31: https://static.finnhub.io/logo/ea701be36180b02128c519975a35fcca2ef8ef5cd412e65e7ff39eb054703270.png | G31: https://www.adicetbio.com/ | H31: B | I31: Medium | J31: B | K31: Medium | L31: BB | M31: Medium | N31: 215 | O31: 211 | P31: 305 | Q31: 731 | R31: 44667 | S31: B | T31: Medium | U31: 1720580
A32: abcl | B32: Abcellera Biologics Inc | C32: USD | D32: NASDAQ NMS - GLOBAL MARKET | E32: Life Sciences Tools and Services | F32: https://static.finnhub.io/logo/cd950365b552eae0cadf348f427e5a4dd05974468d5803b8b63e44da362a5ee9.png | G32: https://www.abcellera.com/ | H32: A | I32: High | J32: BB | K32: Medium | L32: BB | M32: Medium | N32: 540 | O32: 354 | P32: 345 | Q32: 1239 | R32: 44722 | S32: A | T32: High | U32: 1703057
A33: abcb | B33: Ameris Bancorp | C33: USD | D33: NASDAQ NMS - GLOBAL MARKET | E33: Banking | F33: https://static.finnhub.io/logo/8cea9450-80df-11ea-80b8-00000000092a.png | G33: https://www.amerisbank.com/ | H33: B | I33: Medium | J33: BB | K33: Medium | L33: B | M33: Medium | N33: 290 | O33: 300 | P33: 250 | Q33: 840 | R33: 44667 | S33: BB | T33: Medium | U33: 351569
A34: acev | B34: ACE Convergence Acquisition Corp | C34: USD | D34: NASDAQ NMS - GLOBAL MARKET | E34: N/A | F34: https://static.finnhub.io/logo/d86f14d77a3f95acbb00c602a4e2d735df7f2d3cfd22be9263a22876630ae65d.png | G34: http://acev.io/home/ | H34: B | I34: Medium | J34: B | K34: Medium | L34: B | M34: Medium | N34: 225 | O34: 211 | P34: 215 | Q34: 651 | R34: 44722 | S34: B | T34: Medium | U34: 1813658
A35: achl | B35: Achilles Therapeutics PLC | C35: USD | D35: NASDAQ NMS - GLOBAL MARKET | E35: Biotechnology | F35: https://static.finnhub.io/logo/6147e0afabb6d97c0483d7921c255166e49adccf043d5bf956068f9c4c546cae.png | G35: https://www.achillestx.com/ | H35: B | I35: Medium | J35: B | K35: Medium | L35: B | M35: Medium | N35: 230 | O35: 288 | P35: 285 | Q35: 803 | R35: 44722 | S35: BB | T35: Medium | U35: 1830749
A36: achc | B36: Acadia Healthcare Company Inc | C36: USD | D36: NASDAQ NMS - GLOBAL MARKET | E36: Health Care | F36: https://static.finnhub.io/logo/4b6b2e5a4cfce5b1377719219ab5a354a629c9b9fb43067b5993423152fef1fb.png | G36: https://www.acadiahealthcare.com/ | H36: BB | I36: Medium | J36: B | K36: Medium | L36: B | M36: Medium | N36: 330 | O36: 231 | P36: 220 | Q36: 781 | R36: 44667 | S36: BB | T36: Medium | U36: 1520697
A37: aciw | B37: ACI Worldwide Inc | C37: USD | D37: NASDAQ NMS - GLOBAL MARKET | E37: Technology | F37: https://static.finnhub.io/logo/875c5a76-80df-11ea-ab99-00000000092a.png | G37: https://www.aciworldwide.com/ | H37: A | I37: High | J37: BB | K37: Medium | L37: BB | M37: Medium | N37: 500 | O37: 327 | P37: 300 | Q37: 1127 | R37: 44667 | S37: BBB | T37: High | U37: 935036
A38: acls | B38: Axcelis Technologies Inc | C38: USD | D38: NASDAQ NMS - GLOBAL MARKET | E38: Semiconductors | F38: https://static.finnhub.io/logo/88b5f730-80df-11ea-94d0-00000000092a.png | G38: https://www.axcelis.com/ | H38: A | I38: High | J38: BB | K38: Medium | L38: B | M38: Medium | N38: 515 | O38: 306 | P38: 260 | Q38: 1081 | R38: 44667 | S38: BBB | T38: High | U38: 1113232
A39: aciu | B39: AC Immune SA | C39: CHF | D39: NASDAQ NMS - GLOBAL MARKET | E39: Biotechnology | F39: https://static.finnhub.io/logo/f93a1c3e-80db-11ea-a2b4-00000000092a.png | G39: https://www.acimmune.com/ | H39: B | I39: Medium | J39: B | K39: Medium | L39: BB | M39: Medium | N39: 250 | O39: 296 | P39: 305 | Q39: 851 | R39: 44667 | S39: BB | T39: Medium | U39: 1651625
A40: achv | B40: Achieve Life Sciences Inc | C40: USD | D40: NASDAQ NMS - GLOBAL MARKET | E40: Biotechnology | F40: https://static.finnhub.io/logo/bf32de26-80e0-11ea-962e-00000000092a.png | G40: http://achievelifesciences.com/ | H40: B | I40: Medium | J40: B | K40: Medium | L40: BB | M40: Medium | N40: 215 | O40: 222 | P40: 305 | Q40: 742 | R40: 44722 | S40: B | T40: Medium | U40: 949858
...

Sheet Benchmarking
A1: ESG COMPANY BENCHMARKING
A2: Company-level scores vs. dynamically calculated industry benchmarks | Source: Raw Data (722 companies) | Positive = above industry average, Negative = below
A3: Company | B3: Ticker | C3: Industry | D3: Environmental Score | E3: Social Score | F3: Governance Score | G3: Total ESG Score | H3: Industry Avg ESG | I3: ESG vs Industry | J3: ESG vs Industry % | K3: Industry Avg Environmental | L3: Environmental vs Industry | M3: Industry Avg Social | N3: Social vs Industry | O3: Industry Avg Governance | P3: Governance vs Industry
A4: ='Raw Data'!B2 -> Walt Disney Co | B4: ='Raw Data'!A2 -> dis | C4: =IF('Raw Data'!E2="N/A","Unclassified",TRIM(SUBSTITUTE('Raw Data'!E2," and "," & "))) -> Media | D4: ='Raw Data'!N2 -> 510 | E4: ='Raw Data'!O2 -> 316 | F4: ='Raw Data'!P2 -> 321 | G4: ='Raw Data'!Q2 -> 1147 | H4: =INDEX('Industry Stats'!$F$2:$F$49,MATCH($C4,'Industry Stats'!$A$2:$A$49,0)) -> 935.26087 | I4: =G4-H4 -> 211.73913 | J4: =I4/H4 -> 0.2263958 | K4: =INDEX('Industry Stats'!$C$2:$C$49,MATCH($C4,'Industry Stats'!$A$2:$A$49,0)) -> 346.91304 | L4: =D4-K4 -> 163.08696 | M4: =INDEX('Industry Stats'!$D$2:$D$49,MATCH($C4,'Industry Stats'!$A$2:$A$49,0)) -> 313 | N4: =E4-M4 -> 3 | O4: =INDEX('Industry Stats'!$E$2:$E$49,MATCH($C4,'Industry Stats'!$A$2:$A$49,0)) -> 275.34783 | P4: =F4-O4 -> 45.652174 | R4: =G4+(10000-ROW())/10000000 -> 1147.001 | S4: =D4+(10000-ROW())/10000000 -> 510.001 | T4: =E4+(10000-ROW())/10000000 -> 316.001 | U4: =F4+(10000-ROW())/10000000 -> 321.001 | V4: =I4+(10000-ROW())/10000000 -> 211.74013 | W4: =-I4+(10000-ROW())/10000000 -> -211.73813
A5: ='Raw Data'!B3 -> General Motors Co | B5: ='Raw Data'!A3 -> gm | C5: =IF('Raw Data'!E3="N/A","Unclassified",TRIM(SUBSTITUTE('Raw Data'!E3," and "," & "))) -> Automobiles | D5: ='Raw Data'!N3 -> 510 | E5: ='Raw Data'!O3 -> 303 | F5: ='Raw Data'!P3 -> 255 | G5: ='Raw Data'!Q3 -> 1068 | H5: =INDEX('Industry Stats'!$F$2:$F$49,MATCH($C5,'Industry Stats'!$A$2:$A$49,0)) -> 859.25 | I5: =G5-H5 -> 208.75 | J5: =I5/H5 -> 0.24294443 | K5: =INDEX('Industry Stats'!$C$2:$C$49,MATCH($C5,'Industry Stats'!$A$2:$A$49,0)) -> 393 | L5: =D5-K5 -> 117 | M5: =INDEX('Industry Stats'!$D$2:$D$49,MATCH($C5,'Industry Stats'!$A$2:$A$49,0)) -> 229.25 | N5: =E5-M5 -> 73.75 | O5: =INDEX('Industry Stats'!$E$2:$E$49,MATCH($C5,'Industry Stats'!$A$2:$A$49,0)) -> 237 | P5: =F5-O5 -> 18 | R5: =G5+(10000-ROW())/10000000 -> 1068.001 | S5: =D5+(10000-ROW())/10000000 -> 510.001 | T5: =E5+(10000-ROW())/10000000 -> 303.001 | U5: =F5+(10000-ROW())/10000000 -> 255.001 | V5: =I5+(10000-ROW())/10000000 -> 208.751 | W5: =-I5+(10000-ROW())/10000000 -> -208.749
A6: ='Raw Data'!B4 -> WW Grainger Inc | B6: ='Raw Data'!A4 -> gww | C6: =IF('Raw Data'!E4="N/A","Unclassified",TRIM(SUBSTITUTE('Raw Data'!E4," and "," & "))) -> Trading Companies & Distributors | D6: ='Raw Data'!N4 -> 255 | E6: ='Raw Data'!O4 -> 385 | F6: ='Raw Data'!P4 -> 240 | G6: ='Raw Data'!Q4 -> 880 | H6: =INDEX('Industry Stats'!$F$2:$F$49,MATCH($C6,'Industry Stats'!$A$2:$A$49,0)) -> 885.2 | I6: =G6-H6 -> -5.2 | J6: =I6/H6 -> -0.0058743787 | K6: =INDEX('Industry Stats'!$C$2:$C$49,MATCH($C6,'Industry Stats'!$A$2:$A$49,0)) -> 332.8 | L6: =D6-K6 -> -77.8 | M6: =INDEX('Industry Stats'!$D$2:$D$49,MATCH($C6,'Industry Stats'!$A$2:$A$49,0)) -> 302.4 | N6: =E6-M6 -> 82.6 | O6: =INDEX('Industry Stats'!$E$2:$E$49,MATCH($C6,'Industry Stats'!$A$2:$A$49,0)) -> 250 | P6: =F6-O6 -> -10 | R6: =G6+(10000-ROW())/10000000 -> 880.001 | S6: =D6+(10000-ROW())/10000000 -> 255.001 | T6: =E6+(10000-ROW())/10000000 -> 385.001 | U6: =F6+(10000-ROW())/10000000 -> 240.001 | V6: =I6+(10000-ROW())/10000000 -> -5.1990006 | W6: =-I6+(10000-ROW())/10000000 -> 5.2009994
A7: ='Raw Data'!B5 -> Mohawk Industries Inc | B7: ='Raw Data'!A5 -> mhk | C7: =IF('Raw Data'!E5="N/A","Unclassified",TRIM(SUBSTITUTE('Raw Data'!E5," and "," & "))) -> Consumer products | D7: ='Raw Data'!N5 -> 570 | E7: ='Raw Data'!O5 -> 298 | F7: ='Raw Data'!P5 -> 303 | G7: ='Raw Data'!Q5 -> 1171 | H7: =INDEX('Industry Stats'!$F$2:$F$49,MATCH($C7,'Industry Stats'!$A$2:$A$49,0)) -> 945.55 | I7: =G7-H7 -> 225.45 | J7: =I7/H7 -> 0.23843266 | K7: =INDEX('Industry Stats'!$C$2:$C$49,MATCH($C7,'Industry Stats'!$A$2:$A$49,0)) -> 384.9 | L7: =D7-K7 -> 185.1 | M7: =INDEX('Industry Stats'!$D$2:$D$49,MATCH($C7,'Industry Stats'!$A$2:$A$49,0)) -> 285.7 | N7: =E7-M7 -> 12.3 | O7: =INDEX('Industry Stats'!$E$2:$E$49,MATCH($C7,'Industry Stats'!$A$2:$A$49,0)) -> 274.95 | P7: =F7-O7 -> 28.05 | R7: =G7+(10000-ROW())/10000000 -> 1171.001 | S7: =D7+(10000-ROW())/10000000 -> 570.001 | T7: =E7+(10000-ROW())/10000000 -> 298.001 | U7: =F7+(10000-ROW())/10000000 -> 303.001 | V7: =I7+(10000-ROW())/10000000 -> 225.451 | W7: =-I7+(10000-ROW())/10000000 -> -225.449
A8: ='Raw Data'!B6 -> Live Nation Entertainment Inc | B8: ='Raw Data'!A6 -> lyv | C8: =IF('Raw Data'!E6="N/A","Unclassified",TRIM(SUBSTITUTE('Raw Data'!E6," and "," & "))) -> Media | D8: ='Raw Data'!N6 -> 492 | E8: ='Raw Data'!O6 -> 310 | F8: ='Raw Data'!P6 -> 250 | G8: ='Raw Data'!Q6 -> 1052 | H8: =INDEX('Industry Stats'!$F$2:$F$49,MATCH($C8,'Industry Stats'!$A$2:$A$49,0)) -> 935.26087 | I8: =G8-H8 -> 116.73913 | J8: =I8/H8 -> 0.12481986 | K8: =INDEX('Industry Stats'!$C$2:$C$49,MATCH($C8,'Industry Stats'!$A$2:$A$49,0)) -> 346.91304 | L8: =D8-K8 -> 145.08696 | M8: =INDEX('Industry Stats'!$D$2:$D$49,MATCH($C8,'Industry Stats'!$A$2:$A$49,0)) -> 313 | N8: =E8-M8 -> -3 | O8: =INDEX('Industry Stats'!$E$2:$E$49,MATCH($C8,'Industry Stats'!$A$2:$A$49,0)) -> 275.34783 | P8: =F8-O8 -> -25.347826 | R8: =G8+(10000-ROW())/10000000 -> 1052.001 | S8: =D8+(10000-ROW())/10000000 -> 492.001 | T8: =E8+(10000-ROW())/10000000 -> 310.001 | U8: =F8+(10000-ROW())/10000000 -> 250.001 | V8: =I8+(10000-ROW())/10000000 -> 116.74013 | W8: =-I8+(10000-ROW())/10000000 -> -116.73813
A9: ='Raw Data'!B7 -> Las Vegas Sands Corp | B9: ='Raw Data'!A7 -> lvs | C9: =IF('Raw Data'!E7="N/A","Unclassified",TRIM(SUBSTITUTE('Raw Data'!E7," and "," & "))) -> Hotels Restaurants & Leisure | D9: ='Raw Data'!N7 -> 547 | E9: ='Raw Data'!O7 -> 318 | F9: ='Raw Data'!P7 -> 313 | G9: ='Raw Data'!Q7 -> 1178 | H9: =INDEX('Industry Stats'!$F$2:$F$49,MATCH($C9,'Industry Stats'!$A$2:$A$49,0)) -> 918.86364 | I9: =G9-H9 -> 259.13636 | J9: =I9/H9 -> 0.2820183 | K9: =INDEX('Industry Stats'!$C$2:$C$49,MATCH($C9,'Industry Stats'!$A$2:$A$49,0)) -> 374.63636 | L9: =D9-K9 -> 172.36364 | M9: =INDEX('Industry Stats'!$D$2:$D$49,MATCH($C9,'Industry Stats'!$A$2:$A$49,0)) -> 283.04545 | N9: =E9-M9 -> 34.954545 | O9: =INDEX('Industry Stats'!$E$2:$E$49,MATCH($C9,'Industry Stats'!$A$2:$A$49,0)) -> 261.18182 | P9: =F9-O9 -> 51.818182 | R9: =G9+(10000-ROW())/10000000 -> 1178.001 | S9: =D9+(10000-ROW())/10000000 -> 547.001 | T9: =E9+(10000-ROW())/10000000 -> 318.001 | U9: =F9+(10000-ROW())/10000000 -> 313.001 | V9: =I9+(10000-ROW())/10000000 -> 259.13736 | W9: =-I9+(10000-ROW())/10000000 -> -259.13536
A10: ='Raw Data'!B8 -> Clorox Co | B10: ='Raw Data'!A8 -> clx | C10: =IF('Raw Data'!E8="N/A","Unclassified",TRIM(SUBSTITUTE('Raw Data'!E8," and "," & "))) -> Consumer products | D10: ='Raw Data'!N8 -> 560 | E10: ='Raw Data'!O8 -> 350 | F10: ='Raw Data'!P8 -> 345 | G10: ='Raw Data'!Q8 -> 1255 | H10: =INDEX('Industry Stats'!$F$2:$F$49,MATCH($C10,'Industry Stats'!$A$2:$A$49,0)) -> 945.55 | I10: =G10-H10 -> 309.45 | J10: =I10/H10 -> 0.32726984 | K10: =INDEX('Industry Stats'!$C$2:$C$49,MATCH($C10,'Industry Stats'!$A$2:$A$49,0)) -> 384.9 | L10: =D10-K10 -> 175.1 | M10: =INDEX('Industry Stats'!$D$2:$D$49,MATCH($C10,'Industry Stats'!$A$2:$A$49,0)) -> 285.7 | N10: =E10-M10 -> 64.3 | O10: =INDEX('Industry Stats'!$E$2:$E$49,MATCH($C10,'Industry Stats'!$A$2:$A$49,0)) -> 274.95 | P10: =F10-O10 -> 70.05 | R10: =G10+(10000-ROW())/10000000 -> 1255.001 | S10: =D10+(10000-ROW())/10000000 -> 560.001 | T10: =E10+(10000-ROW())/10000000 -> 350.001 | U10: =F10+(10000-ROW())/10000000 -> 345.001 | V10: =I10+(10000-ROW())/10000000 -> 309.451 | W10: =-I10+(10000-ROW())/10000000 -> -309.449
A11: ='Raw Data'!B9 -> ATA Creativity Global | B11: ='Raw Data'!A9 -> aacg | C11: =IF('Raw Data'!E9="N/A","Unclassified",TRIM(SUBSTITUTE('Raw Data'!E9," and "," & "))) -> Diversified Consumer Services | D11: ='Raw Data'!N9 -> 203 | E11: ='Raw Data'!O9 -> 200 | F11: ='Raw Data'!P9 -> 205 | G11: ='Raw Data'!Q9 -> 608 | H11: =INDEX('Industry Stats'!$F$2:$F$49,MATCH($C11,'Industry Stats'!$A$2:$A$49,0)) -> 739.33333 | I11: =G11-H11 -> -131.33333 | J11: =I11/H11 -> -0.17763751 | K11: =INDEX('Industry Stats'!$C$2:$C$49,MATCH($C11,'Industry Stats'!$A$2:$A$49,0)) -> 286 | L11: =D11-K11 -> -83 | M11: =INDEX('Industry Stats'!$D$2:$D$49,MATCH($C11,'Industry Stats'!$A$2:$A$49,0)) -> 233.33333 | N11: =E11-M11 -> -33.333333 | O11: =INDEX('Industry Stats'!$E$2:$E$49,MATCH($C11,'Industry Stats'!$A$2:$A$49,0)) -> 220 | P11: =F11-O11 -> -15 | R11: =G11+(10000-ROW())/10000000 -> 608.001 | S11: =D11+(10000-ROW())/10000000 -> 203.001 | T11: =E11+(10000-ROW())/10000000 -> 200.001 | U11: =F11+(10000-ROW())/10000000 -> 205.001 | V11: =I11+(10000-ROW())/10000000 -> -131.33233 | W11: =-I11+(10000-ROW())/10000000 -> 131.33433
A12: ='Raw Data'!B10 -> American Airlines Group Inc | B12: ='Raw Data'!A10 -> aal | C12: =IF('Raw Data'!E10="N/A","Unclassified",TRIM(SUBSTITUTE('Raw Data'!E10," and "," & "))) -> Airlines | D12: ='Raw Data'!N10 -> 270 | E12: ='Raw Data'!O10 -> 211 | F12: ='Raw Data'!P10 -> 265 | G12: ='Raw Data'!Q10 -> 746 | H12: =INDEX('Industry Stats'!$F$2:$F$49,MATCH($C12,'Industry Stats'!$A$2:$A$49,0)) -> 838.71429 | I12: =G12-H12 -> -92.714286 | J12: =I12/H12 -> -0.11054335 | K12: =INDEX('Industry Stats'!$C$2:$C$49,MATCH($C12,'Industry Stats'!$A$2:$A$49,0)) -> 326.71429 | L12: =D12-K12 -> -56.714286 | M12: =INDEX('Industry Stats'!$D$2:$D$49,MATCH($C12,'Industry Stats'!$A$2:$A$49,0)) -> 265.71429 | N12: =E12-M12 -> -54.714286 | O12: =INDEX('Industry Stats'!$E$2:$E$49,MATCH($C12,'Industry Stats'!$A$2:$A$49,0)) -> 246.28571 | P12: =F12-O12 -> 18.714286 | R12: =G12+(10000-ROW())/10000000 -> 746.001 | S12: =D12+(10000-ROW())/10000000 -> 270.001 | T12: =E12+(10000-ROW())/10000000 -> 211.001 | U12: =F12+(10000-ROW())/10000000 -> 265.001 | V12: =I12+(10000-ROW())/10000000 -> -92.713287 | W12: =-I12+(10000-ROW())/10000000 -> 92.715285
A13: ='Raw Data'!B11 -> Atlantic American Corp | B13: ='Raw Data'!A11 -> aame | C13: =IF('Raw Data'!E11="N/A","Unclassified",TRIM(SUBSTITUTE('Raw Data'!E11," and "," & "))) -> Insurance | D13: ='Raw Data'!N11 -> 220 | E13: ='Raw Data'!O11 -> 221 | F13: ='Raw Data'!P11 -> 300 | G13: ='Raw Data'!Q11 -> 741 | H13: =INDEX('Industry Stats'!$F$2:$F$49,MATCH($C13,'Industry Stats'!$A$2:$A$49,0)) -> 1012.3704 | I13: =G13-H13 -> -271.37037 | J13: =I13/H13 -> -0.26805444 | K13: =INDEX('Industry Stats'!$C$2:$C$49,MATCH($C13,'Industry Stats'!$A$2:$A$49,0)) -> 425.25926 | L13: =D13-K13 -> -205.25926 | M13: =INDEX('Industry Stats'!$D$2:$D$49,MATCH($C13,'Industry Stats'!$A$2:$A$49,0)) -> 295.66667 | N13: =E13-M13 -> -74.666667 | O13: =INDEX('Industry Stats'!$E$2:$E$49,MATCH($C13,'Industry Stats'!$A$2:$A$49,0)) -> 291.44444 | P13: =F13-O13 -> 8.5555556 | R13: =G13+(10000-ROW())/10000000 -> 741.001 | S13: =D13+(10000-ROW())/10000000 -> 220.001 | T13: =E13+(10000-ROW())/10000000 -> 221.001 | U13: =F13+(10000-ROW())/10000000 -> 300.001 | V13: =I13+(10000-ROW())/10000000 -> -271.36937 | W13: =-I13+(10000-ROW())/10000000 -> 271.37137
A14: ='Raw Data'!B12 -> Applied Optoelectronics Inc | B14: ='Raw Data'!A12 -> aaoi | C14: =IF('Raw Data'!E12="N/A","Unclassified",TRIM(SUBSTITUTE('Raw Data'!E12," and "," & "))) -> Communications | D14: ='Raw Data'!N12 -> 311 | E14: ='Raw Data'!O12 -> 256 | F14: ='Raw Data'!P12 -> 218 | G14: ='Raw Data'!Q12 -> 785 | H14: =INDEX('Industry Stats'!$F$2:$F$49,MATCH($C14,'Industry Stats'!$A$2:$A$49,0)) -> 938.22222 | I14: =G14-H14 -> -153.22222 | J14: =I14/H14 -> -0.16331123 | K14: =INDEX('Industry Stats'!$C$2:$C$49,MATCH($C14,'Industry Stats'!$A$2:$A$49,0)) -> 385 | L14: =D14-K14 -> -74 | M14: =INDEX('Industry Stats'!$D$2:$D$49,MATCH($C14,'Industry Stats'!$A$2:$A$49,0)) -> 278.77778 | N14: =E14-M14 -> -22.777778 | O14: =INDEX('Industry Stats'!$E$2:$E$49,MATCH($C14,'Industry Stats'!$A$2:$A$49,0)) -> 274.44444 | P14: =F14-O14 -> -56.444444 | R14: =G14+(10000-ROW())/10000000 -> 785.001 | S14: =D14+(10000-ROW())/10000000 -> 311.001 | T14: =E14+(10000-ROW())/10000000 -> 256.001 | U14: =F14+(10000-ROW())/10000000 -> 218.001 | V14: =I14+(10000-ROW())/10000000 -> -153.22122 | W14: =-I14+(10000-ROW())/10000000 -> 153.22322
A15: ='Raw Data'!B13 -> Aaon Inc | B15: ='Raw Data'!A13 -> aaon | C15: =IF('Raw Data'!E13="N/A","Unclassified",TRIM(SUBSTITUTE('Raw Data'!E13," and "," & "))) -> Building | D15: ='Raw Data'!N13 -> 500 | E15: ='Raw Data'!O13 -> 300 | F15: ='Raw Data'!P13 -> 223 | G15: ='Raw Data'!Q13 -> 1023 | H15: =INDEX('Industry Stats'!$F$2:$F$49,MATCH($C15,'Industry Stats'!$A$2:$A$49,0)) -> 1074.2 | I15: =G15-H15 -> -51.2 | J15: =I15/H15 -> -0.047663377 | K15: =INDEX('Industry Stats'!$C$2:$C$49,MATCH($C15,'Industry Stats'!$A$2:$A$49,0)) -> 476.7 | L15: =D15-K15 -> 23.3 | M15: =INDEX('Industry Stats'!$D$2:$D$49,MATCH($C15,'Industry Stats'!$A$2:$A$49,0)) -> 305.1 | N15: =E15-M15 -> -5.1 | O15: =INDEX('Industry Stats'!$E$2:$E$49,MATCH($C15,'Industry Stats'!$A$2:$A$49,0)) -> 292.4 | P15: =F15-O15 -> -69.4 | R15: =G15+(10000-ROW())/10000000 -> 1023.001 | S15: =D15+(10000-ROW())/10000000 -> 500.001 | T15: =E15+(10000-ROW())/10000000 -> 300.001 | U15: =F15+(10000-ROW())/10000000 -> 223.001 | V15: =I15+(10000-ROW())/10000000 -> -51.199002 | W15: =-I15+(10000-ROW())/10000000 -> 51.200999
... A725: ='Raw Data'!B723 -> HEICO Corp | B725: ='Raw Data'!A723 -> hei | C725: =IF('Raw Data'!E723="N/A","Unclassified",TRIM(SUBSTITUTE('Raw Data'!E723," and "," & "))) -> Aerospace & Defense | D725: ='Raw Data'!N723 -> 225 | E725: ='Raw Data'!O723 -> 203 | F725: ='Raw Data'!P723 -> 205 | G725: ='Raw Data'!Q723 -> 633 | H725: =INDEX('Industry Stats'!$F$2:$F$49,MATCH($C725,'Industry Stats'!$A$2:$A$49,0)) -> 1048.1818 | I725: =G725-H725 -> -415.18182 | J725: =I725/H725 -> -0.39609714 | K725: =INDEX('Industry Stats'!$C$2:$C$49,MATCH($C725,'Industry Stats'!$A$2:$A$49,0)) -> 461.36364 | L725: =D725-K725 -> -236.36364 | M725: =INDEX('Industry Stats'!$D$2:$D$49,MATCH($C725,'Industry Stats'!$A$2:$A$49,0)) -> 296.36364 | N725: =E725-M725 -> -93.363636 | O725: =INDEX('Industry Stats'!$E$2:$E$49,MATCH($C725,'Industry Stats'!$A$2:$A$49,0)) -> 290.45455 | P725: =F725-O725 -> -85.454545 | R725: =G725+(10000-ROW())/10000000 -> 633.00093 | S725: =D725+(10000-ROW())/10000000 -> 225.00093 | T725: =E725+(10000-ROW())/10000000 -> 203.00093 | U725: =F725+(10000-ROW())/10000000 -> 205.00093 | V725: =I725+(10000-ROW())/10000000 -> -415.18089 | W725: =-I725+(10000-ROW())/10000000 -> 415.18275

Sheet Pillar Analysis
A1: PILLAR ANALYSIS (E / S / G)
A2: Moves beyond the aggregate ESG score to examine balance and imbalance across Environmental, Social and Governance pillars. "Pillar Range", "percentile" and "Investigation Flag" are project-created analytical measures for this workbook only — they are NOT an official ESG risk rating, methodology, or third-party score of any kind.
A3: Company | B3: Ticker | C3: Industry | D3: Environmental Score | E3: Social Score | F3: Governance Score | G3: Total ESG Score | H3: Strongest Pillar | I3: Weakest Pillar | J3: E - S Gap | K3: S - G Gap | L3: E - G Gap | M3: Pillar Range (Max-Min) | N3: Total ESG Percentile | O3: Weakest Pillar Percentile | P3: Pillar Imbalance Gap | Q3: Investigation Flag (Project-Created Analytical Flag, Not an Official ESG Rating)
A4: =Benchmarking!A4 -> Walt Disney Co | B4: =Benchmarking!B4 -> dis | C4: =Benchmarking!C4 -> Media | D4: =Benchmarking!D4 -> 510 | E4: =Benchmarking!E4 -> 316 | F4: =Benchmarking!F4 -> 321 | G4: =Benchmarking!G4 -> 1147 | H4: =IF(AND(D4>=E4,D4>=F4),"Environmental",IF(AND(E4>=D4,E4>=F4),"Social","Governance")) -> Environmental | I4: =IF(AND(D4<=E4,D4<=F4),"Environmental",IF(AND(E4<=D4,E4<=F4),"Social","Governance")) -> Social | J4: =D4-E4 -> 194 | K4: =E4-F4 -> -5 | L4: =D4-F4 -> 189 | M4: =MAX(D4:F4)-MIN(D4:F4) -> 194 | N4: =RANK(G4,$G$4:$G$725,1)/COUNT($G$4:$G$725) -> 0.76038781 | O4: =MIN(RANK(D4,$D$4:$D$725,1)/COUNT($D$4:$D$725),RANK(E4,$E$4:$E$725,1)/COUNT($E$4:$E$725),RANK(F4,$F$4:$F$725,1)/COUNT($F$4:$F$725)) -> 0.66620499 | P4: =N4-O4 -> 0.094182825 | Q4: =IF(AND(N4>=0.7,P4>=0.4),"High ESG / weak pillar (analytical flag - not an ESG rating) - warrants investigation","") | S4: =M4+(10000-ROW())/10000000 -> 194.001 | T4: =P4+(10000-ROW())/10000000 -> 0.095182425
A5: =Benchmarking!A5 -> General Motors Co | B5: =Benchmarking!B5 -> gm | C5: =Benchmarking!C5 -> Automobiles | D5: =Benchmarking!D5 -> 510 | E5: =Benchmarking!E5 -> 303 | F5: =Benchmarking!F5 -> 255 | G5: =Benchmarking!G5 -> 1068 | H5: =IF(AND(D5>=E5,D5>=F5),"Environmental",IF(AND(E5>=D5,E5>=F5),"Social","Governance")) -> Environmental | I5: =IF(AND(D5<=E5,D5<=F5),"Environmental",IF(AND(E5<=D5,E5<=F5),"Social","Governance")) -> Governance | J5: =D5-E5 -> 207 | K5: =E5-F5 -> 48 | L5: =D5-F5 -> 255 | M5: =MAX(D5:F5)-MIN(D5:F5) -> 255 | N5: =RANK(G5,$G$4:$G$725,1)/COUNT($G$4:$G$725) -> 0.52770083 | O5: =MIN(RANK(D5,$D$4:$D$725,1)/COUNT($D$4:$D$725),RANK(E5,$E$4:$E$725,1)/COUNT($E$4:$E$725),RANK(F5,$F$4:$F$725,1)/COUNT($F$4:$F$725)) -> 0.31024931 | P5: =N5-O5 -> 0.21745152 | Q5: =IF(AND(N5>=0.7,P5>=0.4),"High ESG / weak pillar (analytical flag - not an ESG rating) - warrants investigation","") | S5: =M5+(10000-ROW())/10000000 -> 255.001 | T5: =P5+(10000-ROW())/10000000 -> 0.21845102
A6: =Benchmarking!A6 -> WW Grainger Inc | B6: =Benchmarking!B6 -> gww | C6: =Benchmarking!C6 -> Trading Companies & Distributors | D6: =Benchmarking!D6 -> 255 | E6: =Benchmarking!E6 -> 385 | F6: =Benchmarking!F6 -> 240 | G6: =Benchmarking!G6 -> 880 | H6: =IF(AND(D6>=E6,D6>=F6),"Environmental",IF(AND(E6>=D6,E6>=F6),"Social","Governance")) -> Social | I6: =IF(AND(D6<=E6,D6<=F6),"Environmental",IF(AND(E6<=D6,E6<=F6),"Social","Governance")) -> Governance | J6: =D6-E6 -> -130 | K6: =E6-F6 -> 145 | L6: =D6-F6 -> 15 | M6: =MAX(D6:F6)-MIN(D6:F6) -> 145 | N6: =RANK(G6,$G$4:$G$725,1)/COUNT($G$4:$G$725) -> 0.35734072 | O6: =MIN(RANK(D6,$D$4:$D$725,1)/COUNT($D$4:$D$725),RANK(E6,$E$4:$E$725,1)/COUNT($E$4:$E$725),RANK(F6,$F$4:$F$725,1)/COUNT($F$4:$F$725)) -> 0.27423823 | P6: =N6-O6 -> 0.083102493 | Q6: =IF(AND(N6>=0.7,P6>=0.4),"High ESG / weak pillar (analytical flag - not an ESG rating) - warrants investigation","") | S6: =M6+(10000-ROW())/10000000 -> 145.001 | T6: =P6+(10000-ROW())/10000000 -> 0.084101893
A7: =Benchmarking!A7 -> Mohawk Industries Inc | B7: =Benchmarking!B7 -> mhk | C7: =Benchmarking!C7 -> Consumer products | D7: =Benchmarking!D7 -> 570 | E7: =Benchmarking!E7 -> 298 | F7: =Benchmarking!F7 -> 303 | G7: =Benchmarking!G7 -> 1171 | H7: =IF(AND(D7>=E7,D7>=F7),"Environmental",IF(AND(E7>=D7,E7>=F7),"Social","Governance")) -> Environmental | I7: =IF(AND(D7<=E7,D7<=F7),"Environmental",IF(AND(E7<=D7,E7<=F7),"Social","Governance")) -> Social | J7: =D7-E7 -> 272 | K7: =E7-F7 -> -5 | L7: =D7-F7 -> 267 | M7: =MAX(D7:F7)-MIN(D7:F7) -> 272 | N7: =RANK(G7,$G$4:$G$725,1)/COUNT($G$4:$G$725) -> 0.82825485 | O7: =MIN(RANK(D7,$D$4:$D$725,1)/COUNT($D$4:$D$725),RANK(E7,$E$4:$E$725,1)/COUNT($E$4:$E$725),RANK(F7,$F$4:$F$725,1)/COUNT($F$4:$F$725)) -> 0.35872576 | P7: =N7-O7 -> 0.46952909 | Q7: =IF(AND(N7>=0.7,P7>=0.4),"High ESG / weak pillar (analytical flag - not an ESG rating) - warrants investigation","") -> High ESG / weak pillar (analytical flag - not an ESG rating) - warrants investigation | S7: =M7+(10000-ROW())/10000000 -> 272.001 | T7: =P7+(10000-ROW())/10000000 -> 0.47052839
A8: =Benchmarking!A8 -> Live Nation Entertainment Inc | B8: =Benchmarking!B8 -> lyv | C8: =Benchmarking!C8 -> Media | D8: =Benchmarking!D8 -> 492 | E8: =Benchmarking!E8 -> 310 | F8: =Benchmarking!F8 -> 250 | G8: =Benchmarking!G8 -> 1052 | H8: =IF(AND(D8>=E8,D8>=F8),"Environmental",IF(AND(E8>=D8,E8>=F8),"Social","Governance")) -> Environmental | I8: =IF(AND(D8<=E8,D8<=F8),"Environmental",IF(AND(E8<=D8,E8<=F8),"Social","Governance")) -> Governance | J8: =D8-E8 -> 182 | K8: =E8-F8 -> 60 | L8: =D8-F8 -> 242 | M8: =MAX(D8:F8)-MIN(D8:F8) -> 242 | N8: =RANK(G8,$G$4:$G$725,1)/COUNT($G$4:$G$725) -> 0.50692521 | O8: =MIN(RANK(D8,$D$4:$D$725,1)/COUNT($D$4:$D$725),RANK(E8,$E$4:$E$725,1)/COUNT($E$4:$E$725),RANK(F8,$F$4:$F$725,1)/COUNT($F$4:$F$725)) -> 0.29639889 | P8: =N8-O8 -> 0.21052632 | Q8: =IF(AND(N8>=0.7,P8>=0.4),"High ESG / weak pillar (analytical flag - not an ESG rating) - warrants investigation","") | S8: =M8+(10000-ROW())/10000000 -> 242.001 | T8: =P8+(10000-ROW())/10000000 -> 0.21152552
A9: =Benchmarking!A9 -> Las Vegas Sands Corp | B9: =Benchmarking!B9 -> lvs | C9: =Benchmarking!C9 -> Hotels Restaurants & Leisure | D9: =Benchmarking!D9 -> 547 | E9: =Benchmarking!E9 -> 318 | F9: =Benchmarking!F9 -> 313 | G9: =Benchmarking!G9 -> 1178 | H9: =IF(AND(D9>=E9,D9>=F9),"Environmental",IF(AND(E9>=D9,E9>=F9),"Social","Governance")) -> Environmental | I9: =IF(AND(D9<=E9,D9<=F9),"Environmental",IF(AND(E9<=D9,E9<=F9),"Social","Governance")) -> Governance | J9: =D9-E9 -> 229 | K9: =E9-F9 -> 5 | L9: =D9-F9 -> 234 | M9: =MAX(D9:F9)-MIN(D9:F9) -> 234 | N9: =RANK(G9,$G$4:$G$725,1)/COUNT($G$4:$G$725) -> 0.84487535 | O9: =MIN(RANK(D9,$D$4:$D$725,1)/COUNT($D$4:$D$725),RANK(E9,$E$4:$E$725,1)/COUNT($E$4:$E$725),RANK(F9,$F$4:$F$725,1)/COUNT($F$4:$F$725)) -> 0.6966759 | P9: =N9-O9 -> 0.14819945 | Q9: =IF(AND(N9>=0.7,P9>=0.4),"High ESG / weak pillar (analytical flag - not an ESG rating) - warrants investigation","") | S9: =M9+(10000-ROW())/10000000 -> 234.001 | T9: =P9+(10000-ROW())/10000000 -> 0.14919855
A10: =Benchmarking!A10 -> Clorox Co | B10: =Benchmarking!B10 -> clx | C10: =Benchmarking!C10 -> Consumer products | D10: =Benchmarking!D10 -> 560 | E10: =Benchmarking!E10 -> 350 | F10: =Benchmarking!F10 -> 345 | G10: =Benchmarking!G10 -> 1255 | H10: =IF(AND(D10>=E10,D10>=F10),"Environmental",IF(AND(E10>=D10,E10>=F10),"Social","Governance")) -> Environmental | I10: =IF(AND(D10<=E10,D10<=F10),"Environmental",IF(AND(E10<=D10,E10<=F10),"Social","Governance")) -> Governance | J10: =D10-E10 -> 210 | K10: =E10-F10 -> 5 | L10: =D10-F10 -> 215 | M10: =MAX(D10:F10)-MIN(D10:F10) -> 215 | N10: =RANK(G10,$G$4:$G$725,1)/COUNT($G$4:$G$725) -> 0.93767313 | O10: =MIN(RANK(D10,$D$4:$D$725,1)/COUNT($D$4:$D$725),RANK(E10,$E$4:$E$725,1)/COUNT($E$4:$E$725),RANK(F10,$F$4:$F$725,1)/COUNT($F$4:$F$725)) -> 0.90443213 | P10: =N10-O10 -> 0.033240997 | Q10: =IF(AND(N10>=0.7,P10>=0.4),"High ESG / weak pillar (analytical flag - not an ESG rating) - warrants investigation","") | S10: =M10+(10000-ROW())/10000000 -> 215.001 | T10: =P10+(10000-ROW())/10000000 -> 0.034239997
A11: =Benchmarking!A11 -> ATA Creativity Global | B11: =Benchmarking!B11 -> aacg | C11: =Benchmarking!C11 -> Diversified Consumer Services | D11: =Benchmarking!D11 -> 203 | E11: =Benchmarking!E11 -> 200 | F11: =Benchmarking!F11 -> 205 | G11: =Benchmarking!G11 -> 608 | H11: =IF(AND(D11>=E11,D11>=F11),"Environmental",IF(AND(E11>=D11,E11>=F11),"Social","Governance")) -> Governance | I11: =IF(AND(D11<=E11,D11<=F11),"Environmental",IF(AND(E11<=D11,E11<=F11),"Social","Governance")) -> Social | J11: =D11-E11 -> 3 | K11: =E11-F11 -> -5 | L11: =D11-F11 -> -2 | M11: =MAX(D11:F11)-MIN(D11:F11) -> 5 | N11: =RANK(G11,$G$4:$G$725,1)/COUNT($G$4:$G$725) -> 0.022160665 | O11: =MIN(RANK(D11,$D$4:$D$725,1)/COUNT($D$4:$D$725),RANK(E11,$E$4:$E$725,1)/COUNT($E$4:$E$725),RANK(F11,$F$4:$F$725,1)/COUNT($F$4:$F$725)) -> 0.0027700831 | P11: =N11-O11 -> 0.019390582 | Q11: =IF(AND(N11>=0.7,P11>=0.4),"High ESG / weak pillar (analytical flag - not an ESG rating) - warrants investigation","") | S11: =M11+(10000-ROW())/10000000 -> 5.0009989 | T11: =P11+(10000-ROW())/10000000 -> 0.020389482
A12: =Benchmarking!A12 -> American Airlines Group Inc | B12: =Benchmarking!B12 -> aal | C12: =Benchmarking!C12 -> Airlines | D12: =Benchmarking!D12 -> 270 | E12: =Benchmarking!E12 -> 211 | F12: =Benchmarking!F12 -> 265 | G12: =Benchmarking!G12 -> 746 | H12: =IF(AND(D12>=E12,D12>=F12),"Environmental",IF(AND(E12>=D12,E12>=F12),"Social","Governance")) -> Environmental | I12: =IF(AND(D12<=E12,D12<=F12),"Environmental",IF(AND(E12<=D12,E12<=F12),"Social","Governance")) -> Social | J12: =D12-E12 -> 59 | K12: =E12-F12 -> -54 | L12: =D12-F12 -> 5 | M12: =MAX(D12:F12)-MIN(D12:F12) -> 59 | N12: =RANK(G12,$G$4:$G$725,1)/COUNT($G$4:$G$725) -> 0.22160665 | O12: =MIN(RANK(D12,$D$4:$D$725,1)/COUNT($D$4:$D$725),RANK(E12,$E$4:$E$725,1)/COUNT($E$4:$E$725),RANK(F12,$F$4:$F$725,1)/COUNT($F$4:$F$725)) -> 0.11357341 | P12: =N12-O12 -> 0.10803324 | Q12: =IF(AND(N12>=0.7,P12>=0.4),"High ESG / weak pillar (analytical flag - not an ESG rating) - warrants investigation","") | S12: =M12+(10000-ROW())/10000000 -> 59.000999 | T12: =P12+(10000-ROW())/10000000 -> 0.10903204
A13: =Benchmarking!A13 -> Atlantic American Corp | B13: =Benchmarking!B13 -> aame | C13: =Benchmarking!C13 -> Insurance | D13: =Benchmarking!D13 -> 220 | E13: =Benchmarking!E13 -> 221 | F13: =Benchmarking!F13 -> 300 | G13: =Benchmarking!G13 -> 741 | H13: =IF(AND(D13>=E13,D13>=F13),"Environmental",IF(AND(E13>=D13,E13>=F13),"Social","Governance")) -> Governance | I13: =IF(AND(D13<=E13,D13<=F13),"Environmental",IF(AND(E13<=D13,E13<=F13),"Social","Governance")) -> Environmental | J13: =D13-E13 -> -1 | K13: =E13-F13 -> -79 | L13: =D13-F13 -> -80 | M13: =MAX(D13:F13)-MIN(D13:F13) -> 80 | N13: =RANK(G13,$G$4:$G$725,1)/COUNT($G$4:$G$725) -> 0.21052632 | O13: =MIN(RANK(D13,$D$4:$D$725,1)/COUNT($D$4:$D$725),RANK(E13,$E$4:$E$725,1)/COUNT($E$4:$E$725),RANK(F13,$F$4:$F$725,1)/COUNT($F$4:$F$725)) -> 0.1468144 | P13: =N13-O13 -> 0.063711911 | Q13: =IF(AND(N13>=0.7,P13>=0.4),"High ESG / weak pillar (analytical flag - not an ESG rating) - warrants investigation","") | S13: =M13+(10000-ROW())/10000000 -> 80.000999 | T13: =P13+(10000-ROW())/10000000 -> 0.064710611
A14: =Benchmarking!A14 -> Applied Optoelectronics Inc | B14: =Benchmarking!B14 -> aaoi | C14: =Benchmarking!C14 -> Communications | D14: =Benchmarking!D14 -> 311 | E14: =Benchmarking!E14 -> 256 | F14: =Benchmarking!F14 -> 218 | G14: =Benchmarking!G14 -> 785 | H14: =IF(AND(D14>=E14,D14>=F14),"Environmental",IF(AND(E14>=D14,E14>=F14),"Social","Governance")) -> Environmental | I14: =IF(AND(D14<=E14,D14<=F14),"Environmental",IF(AND(E14<=D14,E14<=F14),"Social","Governance")) -> Governance | J14: =D14-E14 -> 55 | K14: =E14-F14 -> 38 | L14: =D14-F14 -> 93 | M14: =MAX(D14:F14)-MIN(D14:F14) -> 93 | N14: =RANK(G14,$G$4:$G$725,1)/COUNT($G$4:$G$725) -> 0.27700831 | O14: =MIN(RANK(D14,$D$4:$D$725,1)/COUNT($D$4:$D$725),RANK(E14,$E$4:$E$725,1)/COUNT($E$4:$E$725),RANK(F14,$F$4:$F$725,1)/COUNT($F$4:$F$725)) -> 0.18559557 | P14: =N14-O14 -> 0.091412742 | Q14: =IF(AND(N14>=0.7,P14>=0.4),"High ESG / weak pillar (analytical flag - not an ESG rating) - warrants investigation","") | S14: =M14+(10000-ROW())/10000000 -> 93.000999 | T14: =P14+(10000-ROW())/10000000 -> 0.092411342
A15: =Benchmarking!A15 -> Aaon Inc | B15: =Benchmarking!B15 -> aaon | C15: =Benchmarking!C15 -> Building | D15: =Benchmarking!D15 -> 500 | E15: =Benchmarking!E15 -> 300 | F15: =Benchmarking!F15 -> 223 | G15: =Benchmarking!G15 -> 1023 | H15: =IF(AND(D15>=E15,D15>=F15),"Environmental",IF(AND(E15>=D15,E15>=F15),"Social","Governance")) -> Environmental | I15: =IF(AND(D15<=E15,D15<=F15),"Environmental",IF(AND(E15<=D15,E15<=F15),"Social","Governance")) -> Governance | J15: =D15-E15 -> 200 | K15: =E15-F15 -> 77 | L15: =D15-F15 -> 277 | M15: =MAX(D15:F15)-MIN(D15:F15) -> 277 | N15: =RANK(G15,$G$4:$G$725,1)/COUNT($G$4:$G$725) -> 0.48753463 | O15: =MIN(RANK(D15,$D$4:$D$725,1)/COUNT($D$4:$D$725),RANK(E15,$E$4:$E$725,1)/COUNT($E$4:$E$725),RANK(F15,$F$4:$F$725,1)/COUNT($F$4:$F$725)) -> 0.2132964 | P15: =N15-O15 -> 0.27423823 | Q15: =IF(AND(N15>=0.7,P15>=0.4),"High ESG / weak pillar (analytical flag - not an ESG rating) - warrants investigation","") | S15: =M15+(10000-ROW())/10000000 -> 277.001 | T15: =P15+(10000-ROW())/10000000 -> 0.27523673
... A725: =Benchmarking!A725 -> HEICO Corp | B725: =Benchmarking!B725 -> hei | C725: =Benchmarking!C725 -> Aerospace & Defense | D725: =Benchmarking!D725 -> 225 | E725: =Benchmarking!E725 -> 203 | F725: =Benchmarking!F725 -> 205 | G725: =Benchmarking!G725 -> 633 | H725: =IF(AND(D725>=E725,D725>=F725),"Environmental",IF(AND(E725>=D725,E725>=F725),"Social","Governance")) -> Environmental | I725: =IF(AND(D725<=E725,D725<=F725),"Environmental",IF(AND(E725<=D725,E725<=F725),"Social","Governance")) -> Social | J725: =D725-E725 -> 22 | K725: =E725-F725 -> -2 | L725: =D725-F725 -> 20 | M725: =MAX(D725:F725)-MIN(D725:F725) -> 22 | N725: =RANK(G725,$G$4:$G$725,1)/COUNT($G$4:$G$725) -> 0.063711911 | O725: =MIN(RANK(D725,$D$4:$D$725,1)/COUNT($D$4:$D$725),RANK(E725,$E$4:$E$725,1)/COUNT($E$4:$E$725),RANK(F725,$F$4:$F$725,1)/COUNT($F$4:$F$725)) -> 0.051246537 | P725: =N725-O725 -> 0.012465374 | Q725: =IF(AND(N725>=0.7,P725>=0.4),"High ESG / weak pillar (analytical flag - not an ESG rating) - warrants investigation","") | S725: =M725+(10000-ROW())/10000000 -> 22.000927 | T725: =P725+(10000-ROW())/10000000 -> 0.013392874

Sheet Rankings
A1: RANKINGS & OUTLIERS
A2: All rankings below are fully formula-driven (LARGE / INDEX / MATCH against the Benchmarking and Pillar Analysis sheets) and will recalculate automatically if the underlying data changes. Ties are broken by original row order.
A4: TOP 15 — OVERALL ESG RANKING
A5: Rank | B5: Company | C5: Ticker | D5: Industry | E5: Total ESG Score
A6: 1 | B6: =INDEX(Benchmarking!$A$4:$A$725,MATCH(LARGE(Benchmarking!$R$4:$R$725,1),Benchmarking!$R$4:$R$725,0)) -> Conocophillips | C6: =INDEX(Benchmarking!$B$4:$B$725,MATCH(LARGE(Benchmarking!$R$4:$R$725,1),Benchmarking!$R$4:$R$725,0)) -> cop | D6: =INDEX(Benchmarking!$C$4:$C$725,MATCH(LARGE(Benchmarking!$R$4:$R$725,1),Benchmarking!$R$4:$R$725,0)) -> Energy | E6: =INDEX(Benchmarking!$G$4:$G$725,MATCH(LARGE(Benchmarking!$R$4:$R$725,1),Benchmarking!$R$4:$R$725,0)) -> 1536
A7: 2 | B7: =INDEX(Benchmarking!$A$4:$A$725,MATCH(LARGE(Benchmarking!$R$4:$R$725,2),Benchmarking!$R$4:$R$725,0)) -> Microsoft Corp | C7: =INDEX(Benchmarking!$B$4:$B$725,MATCH(LARGE(Benchmarking!$R$4:$R$725,2),Benchmarking!$R$4:$R$725,0)) -> msft | D7: =INDEX(Benchmarking!$C$4:$C$725,MATCH(LARGE(Benchmarking!$R$4:$R$725,2),Benchmarking!$R$4:$R$725,0)) -> Technology | E7: =INDEX(Benchmarking!$G$4:$G$725,MATCH(LARGE(Benchmarking!$R$4:$R$725,2),Benchmarking!$R$4:$R$725,0)) -> 1533
A8: 3 | B8: =INDEX(Benchmarking!$A$4:$A$725,MATCH(LARGE(Benchmarking!$R$4:$R$725,3),Benchmarking!$R$4:$R$725,0)) -> Edison International | C8: =INDEX(Benchmarking!$B$4:$B$725,MATCH(LARGE(Benchmarking!$R$4:$R$725,3),Benchmarking!$R$4:$R$725,0)) -> eix | D8: =INDEX(Benchmarking!$C$4:$C$725,MATCH(LARGE(Benchmarking!$R$4:$R$725,3),Benchmarking!$R$4:$R$725,0)) -> Utilities | E8: =INDEX(Benchmarking!$G$4:$G$725,MATCH(LARGE(Benchmarking!$R$4:$R$725,3),Benchmarking!$R$4:$R$725,0)) -> 1528
A9: 4 | B9: =INDEX(Benchmarking!$A$4:$A$725,MATCH(LARGE(Benchmarking!$R$4:$R$725,4),Benchmarking!$R$4:$R$725,0)) -> Airbnb Inc | C9: =INDEX(Benchmarking!$B$4:$B$725,MATCH(LARGE(Benchmarking!$R$4:$R$725,4),Benchmarking!$R$4:$R$725,0)) -> abnb | D9: =INDEX(Benchmarking!$C$4:$C$725,MATCH(LARGE(Benchmarking!$R$4:$R$725,4),Benchmarking!$R$4:$R$725,0)) -> Hotels Restaurants & Leisure | E9: =INDEX(Benchmarking!$G$4:$G$725,MATCH(LARGE(Benchmarking!$R$4:$R$725,4),Benchmarking!$R$4:$R$725,0)) -> 1475
A10: 5 | B10: =INDEX(Benchmarking!$A$4:$A$725,MATCH(LARGE(Benchmarking!$R$4:$R$725,5),Benchmarking!$R$4:$R$725,0)) -> Air Products and Chemicals Inc | C10: =INDEX(Benchmarking!$B$4:$B$725,MATCH(LARGE(Benchmarking!$R$4:$R$725,5),Benchmarking!$R$4:$R$725,0)) -> apd | D10: =INDEX(Benchmarking!$C$4:$C$725,MATCH(LARGE(Benchmarking!$R$4:$R$725,5),Benchmarking!$R$4:$R$725,0)) -> Chemicals | E10: =INDEX(Benchmarking!$G$4:$G$725,MATCH(LARGE(Benchmarking!$R$4:$R$725,5),Benchmarking!$R$4:$R$725,0)) -> 1442
A11: 6 | B11: =INDEX(Benchmarking!$A$4:$A$725,MATCH(LARGE(Benchmarking!$R$4:$R$725,6),Benchmarking!$R$4:$R$725,0)) -> Amazon.com Inc | C11: =INDEX(Benchmarking!$B$4:$B$725,MATCH(LARGE(Benchmarking!$R$4:$R$725,6),Benchmarking!$R$4:$R$725,0)) -> amzn | D11: =INDEX(Benchmarking!$C$4:$C$725,MATCH(LARGE(Benchmarking!$R$4:$R$725,6),Benchmarking!$R$4:$R$725,0)) -> Retail | E11: =INDEX(Benchmarking!$G$4:$G$725,MATCH(LARGE(Benchmarking!$R$4:$R$725,6),Benchmarking!$R$4:$R$725,0)) -> 1433
A12: 7 | B12: =INDEX(Benchmarking!$A$4:$A$725,MATCH(LARGE(Benchmarking!$R$4:$R$725,7),Benchmarking!$R$4:$R$725,0)) -> Newmont Corporation | C12: =INDEX(Benchmarking!$B$4:$B$725,MATCH(LARGE(Benchmarking!$R$4:$R$725,7),Benchmarking!$R$4:$R$725,0)) -> nem | D12: =INDEX(Benchmarking!$C$4:$C$725,MATCH(LARGE(Benchmarking!$R$4:$R$725,7),Benchmarking!$R$4:$R$725,0)) -> Metals & Mining | E12: =INDEX(Benchmarking!$G$4:$G$725,MATCH(LARGE(Benchmarking!$R$4:$R$725,7),Benchmarking!$R$4:$R$725,0)) -> 1419
A13: 8 | B13: =INDEX(Benchmarking!$A$4:$A$725,MATCH(LARGE(Benchmarking!$R$4:$R$725,8),Benchmarking!$R$4:$R$725,0)) -> PepsiCo Inc | C13: =INDEX(Benchmarking!$B$4:$B$725,MATCH(LARGE(Benchmarking!$R$4:$R$725,8),Benchmarking!$R$4:$R$725,0)) -> pep | D13: =INDEX(Benchmarking!$C$4:$C$725,MATCH(LARGE(Benchmarking!$R$4:$R$725,8),Benchmarking!$R$4:$R$725,0)) -> Beverages | E13: =INDEX(Benchmarking!$G$4:$G$725,MATCH(LARGE(Benchmarking!$R$4:$R$725,8),Benchmarking!$R$4:$R$725,0)) -> 1417
A14: 9 | B14: =INDEX(Benchmarking!$A$4:$A$725,MATCH(LARGE(Benchmarking!$R$4:$R$725,9),Benchmarking!$R$4:$R$725,0)) -> Exelon Corp | C14: =INDEX(Benchmarking!$B$4:$B$725,MATCH(LARGE(Benchmarking!$R$4:$R$725,9),Benchmarking!$R$4:$R$725,0)) -> exc | D14: =INDEX(Benchmarking!$C$4:$C$725,MATCH(LARGE(Benchmarking!$R$4:$R$725,9),Benchmarking!$R$4:$R$725,0)) -> Utilities | E14: =INDEX(Benchmarking!$G$4:$G$725,MATCH(LARGE(Benchmarking!$R$4:$R$725,9),Benchmarking!$R$4:$R$725,0)) -> 1413
A15: 10 | B15: =INDEX(Benchmarking!$A$4:$A$725,MATCH(LARGE(Benchmarking!$R$4:$R$725,10),Benchmarking!$R$4:$R$725,0)) -> Pioneer Natural Resources Co | C15: =INDEX(Benchmarking!$B$4:$B$725,MATCH(LARGE(Benchmarking!$R$4:$R$725,10),Benchmarking!$R$4:$R$725,0)) -> pxd | D15: =INDEX(Benchmarking!$C$4:$C$725,MATCH(LARGE(Benchmarking!$R$4:$R$725,10),Benchmarking!$R$4:$R$725,0)) -> Energy | E15: =INDEX(Benchmarking!$G$4:$G$725,MATCH(LARGE(Benchmarking!$R$4:$R$725,10),Benchmarking!$R$4:$R$725,0)) -> 1412
A16: 11 | B16: =INDEX(Benchmarking!$A$4:$A$725,MATCH(LARGE(Benchmarking!$R$4:$R$725,11),Benchmarking!$R$4:$R$725,0)) -> Trane Technologies PLC | C16: =INDEX(Benchmarking!$B$4:$B$725,MATCH(LARGE(Benchmarking!$R$4:$R$725,11),Benchmarking!$R$4:$R$725,0)) -> tt | D16: =INDEX(Benchmarking!$C$4:$C$725,MATCH(LARGE(Benchmarking!$R$4:$R$725,11),Benchmarking!$R$4:$R$725,0)) -> Building | E16: =INDEX(Benchmarking!$G$4:$G$725,MATCH(LARGE(Benchmarking!$R$4:$R$725,11),Benchmarking!$R$4:$R$725,0)) -> 1409
A17: 12 | B17: =INDEX(Benchmarking!$A$4:$A$725,MATCH(LARGE(Benchmarking!$R$4:$R$725,12),Benchmarking!$R$4:$R$725,0)) -> Pinnacle West Capital Corp | C17: =INDEX(Benchmarking!$B$4:$B$725,MATCH(LARGE(Benchmarking!$R$4:$R$725,12),Benchmarking!$R$4:$R$725,0)) -> pnw | D17: =INDEX(Benchmarking!$C$4:$C$725,MATCH(LARGE(Benchmarking!$R$4:$R$725,12),Benchmarking!$R$4:$R$725,0)) -> Utilities | E17: =INDEX(Benchmarking!$G$4:$G$725,MATCH(LARGE(Benchmarking!$R$4:$R$725,12),Benchmarking!$R$4:$R$725,0)) -> 1408
A18: 13 | B18: =INDEX(Benchmarking!$A$4:$A$725,MATCH(LARGE(Benchmarking!$R$4:$R$725,13),Benchmarking!$R$4:$R$725,0)) -> Sempra Energy | C18: =INDEX(Benchmarking!$B$4:$B$725,MATCH(LARGE(Benchmarking!$R$4:$R$725,13),Benchmarking!$R$4:$R$725,0)) -> sre | D18: =INDEX(Benchmarking!$C$4:$C$725,MATCH(LARGE(Benchmarking!$R$4:$R$725,13),Benchmarking!$R$4:$R$725,0)) -> Utilities | E18: =INDEX(Benchmarking!$G$4:$G$725,MATCH(LARGE(Benchmarking!$R$4:$R$725,13),Benchmarking!$R$4:$R$725,0)) -> 1396
A19: 14 | B19: =INDEX(Benchmarking!$A$4:$A$725,MATCH(LARGE(Benchmarking!$R$4:$R$725,14),Benchmarking!$R$4:$R$725,0)) -> Marathon Petroleum Corp | C19: =INDEX(Benchmarking!$B$4:$B$725,MATCH(LARGE(Benchmarking!$R$4:$R$725,14),Benchmarking!$R$4:$R$725,0)) -> mpc | D19: =INDEX(Benchmarking!$C$4:$C$725,MATCH(LARGE(Benchmarking!$R$4:$R$725,14),Benchmarking!$R$4:$R$725,0)) -> Energy | E19: =INDEX(Benchmarking!$G$4:$G$725,MATCH(LARGE(Benchmarking!$R$4:$R$725,14),Benchmarking!$R$4:$R$725,0)) -> 1381
A20: 15 | B20: =INDEX(Benchmarking!$A$4:$A$725,MATCH(LARGE(Benchmarking!$R$4:$R$725,15),Benchmarking!$R$4:$R$725,0)) -> WEC Energy Group Inc | C20: =INDEX(Benchmarking!$B$4:$B$725,MATCH(LARGE(Benchmarking!$R$4:$R$725,15),Benchmarking!$R$4:$R$725,0)) -> wec | D20: =INDEX(Benchmarking!$C$4:$C$725,MATCH(LARGE(Benchmarking!$R$4:$R$725,15),Benchmarking!$R$4:$R$725,0)) -> Utilities | E20: =INDEX(Benchmarking!$G$4:$G$725,MATCH(LARGE(Benchmarking!$R$4:$R$725,15),Benchmarking!$R$4:$R$725,0)) -> 1373
A22: TOP 15 — ENVIRONMENTAL RANKING
A23: Rank | B23: Company | C23: Ticker | D23: Industry | E23: Environmental Score
A24: 1 | B24: =INDEX(Benchmarking!$A$4:$A$725,MATCH(LARGE(Benchmarking!$S$4:$S$725,1),Benchmarking!$S$4:$S$725,0)) -> PepsiCo Inc | C24: =INDEX(Benchmarking!$B$4:$B$725,MATCH(LARGE(Benchmarking!$S$4:$S$725,1),Benchmarking!$S$4:$S$725,0)) -> pep | D24: =INDEX(Benchmarking!$C$4:$C$725,MATCH(LARGE(Benchmarking!$S$4:$S$725,1),Benchmarking!$S$4:$S$725,0)) -> Beverages | E24: =INDEX(Benchmarking!$D$4:$D$725,MATCH(LARGE(Benchmarking!$S$4:$S$725,1),Benchmarking!$S$4:$S$725,0)) -> 719
A25: 2 | B25: =INDEX(Benchmarking!$A$4:$A$725,MATCH(LARGE(Benchmarking!$S$4:$S$725,2),Benchmarking!$S$4:$S$725,0)) -> Microsoft Corp | C25: =INDEX(Benchmarking!$B$4:$B$725,MATCH(LARGE(Benchmarking!$S$4:$S$725,2),Benchmarking!$S$4:$S$725,0)) -> msft | D25: =INDEX(Benchmarking!$C$4:$C$725,MATCH(LARGE(Benchmarking!$S$4:$S$725,2),Benchmarking!$S$4:$S$725,0)) -> Technology | E25: =INDEX(Benchmarking!$D$4:$D$725,MATCH(LARGE(Benchmarking!$S$4:$S$725,2),Benchmarking!$S$4:$S$725,0)) -> 715
A26: 3 | B26: =INDEX(Benchmarking!$A$4:$A$725,MATCH(LARGE(Benchmarking!$S$4:$S$725,3),Benchmarking!$S$4:$S$725,0)) -> Air Products and Chemicals Inc | C26: =INDEX(Benchmarking!$B$4:$B$725,MATCH(LARGE(Benchmarking!$S$4:$S$725,3),Benchmarking!$S$4:$S$725,0)) -> apd | D26: =INDEX(Benchmarking!$C$4:$C$725,MATCH(LARGE(Benchmarking!$S$4:$S$725,3),Benchmarking!$S$4:$S$725,0)) -> Chemicals | E26: =INDEX(Benchmarking!$D$4:$D$725,MATCH(LARGE(Benchmarking!$S$4:$S$725,3),Benchmarking!$S$4:$S$725,0)) -> 700
A27: 4 | B27: =INDEX(Benchmarking!$A$4:$A$725,MATCH(LARGE(Benchmarking!$S$4:$S$725,4),Benchmarking!$S$4:$S$725,0)) -> Edison International | C27: =INDEX(Benchmarking!$B$4:$B$725,MATCH(LARGE(Benchmarking!$S$4:$S$725,4),Benchmarking!$S$4:$S$725,0)) -> eix | D27: =INDEX(Benchmarking!$C$4:$C$725,MATCH(LARGE(Benchmarking!$S$4:$S$725,4),Benchmarking!$S$4:$S$725,0)) -> Utilities | E27: =INDEX(Benchmarking!$D$4:$D$725,MATCH(LARGE(Benchmarking!$S$4:$S$725,4),Benchmarking!$S$4:$S$725,0)) -> 700
A28: 5 | B28: =INDEX(Benchmarking!$A$4:$A$725,MATCH(LARGE(Benchmarking!$S$4:$S$725,5),Benchmarking!$S$4:$S$725,0)) -> Consolidated Edison Inc | C28: =INDEX(Benchmarking!$B$4:$B$725,MATCH(LARGE(Benchmarking!$S$4:$S$725,5),Benchmarking!$S$4:$S$725,0)) -> ed | D28: =INDEX(Benchmarking!$C$4:$C$725,MATCH(LARGE(Benchmarking!$S$4:$S$725,5),Benchmarking!$S$4:$S$725,0)) -> Utilities | E28: =INDEX(Benchmarking!$D$4:$D$725,MATCH(LARGE(Benchmarking!$S$4:$S$725,5),Benchmarking!$S$4:$S$725,0)) -> 700
A29: 6 | B29: =INDEX(Benchmarking!$A$4:$A$725,MATCH(LARGE(Benchmarking!$S$4:$S$725,6),Benchmarking!$S$4:$S$725,0)) -> Marathon Petroleum Corp | C29: =INDEX(Benchmarking!$B$4:$B$725,MATCH(LARGE(Benchmarking!$S$4:$S$725,6),Benchmarking!$S$4:$S$725,0)) -> mpc | D29: =INDEX(Benchmarking!$C$4:$C$725,MATCH(LARGE(Benchmarking!$S$4:$S$725,6),Benchmarking!$S$4:$S$725,0)) -> Energy | E29: =INDEX(Benchmarking!$D$4:$D$725,MATCH(LARGE(Benchmarking!$S$4:$S$725,6),Benchmarking!$S$4:$S$725,0)) -> 700
A30: 7 | B30: =INDEX(Benchmarking!$A$4:$A$725,MATCH(LARGE(Benchmarking!$S$4:$S$725,7),Benchmarking!$S$4:$S$725,0)) -> Pioneer Natural Resources Co | C30: =INDEX(Benchmarking!$B$4:$B$725,MATCH(LARGE(Benchmarking!$S$4:$S$725,7),Benchmarking!$S$4:$S$725,0)) -> pxd | D30: =INDEX(Benchmarking!$C$4:$C$725,MATCH(LARGE(Benchmarking!$S$4:$S$725,7),Benchmarking!$S$4:$S$725,0)) -> Energy | E30: =INDEX(Benchmarking!$D$4:$D$725,MATCH(LARGE(Benchmarking!$S$4:$S$725,7),Benchmarking!$S$4:$S$725,0)) -> 700
A31: 8 | B31: =INDEX(Benchmarking!$A$4:$A$725,MATCH(LARGE(Benchmarking!$S$4:$S$725,8),Benchmarking!$S$4:$S$725,0)) -> Sempra Energy | C31: =INDEX(Benchmarking!$B$4:$B$725,MATCH(LARGE(Benchmarking!$S$4:$S$725,8),Benchmarking!$S$4:$S$725,0)) -> sre | D31: =INDEX(Benchmarking!$C$4:$C$725,MATCH(LARGE(Benchmarking!$S$4:$S$725,8),Benchmarking!$S$4:$S$725,0)) -> Utilities | E31: =INDEX(Benchmarking!$D$4:$D$725,MATCH(LARGE(Benchmarking!$S$4:$S$725,8),Benchmarking!$S$4:$S$725,0)) -> 700
A32: 9 | B32: =INDEX(Benchmarking!$A$4:$A$725,MATCH(LARGE(Benchmarking!$S$4:$S$725,9),Benchmarking!$S$4:$S$725,0)) -> Trane Technologies PLC | C32: =INDEX(Benchmarking!$B$4:$B$725,MATCH(LARGE(Benchmarking!$S$4:$S$725,9),Benchmarking!$S$4:$S$725,0)) -> tt | D32: =INDEX(Benchmarking!$C$4:$C$725,MATCH(LARGE(Benchmarking!$S$4:$S$725,9),Benchmarking!$S$4:$S$725,0)) -> Building | E32: =INDEX(Benchmarking!$D$4:$D$725,MATCH(LARGE(Benchmarking!$S$4:$S$725,9),Benchmarking!$S$4:$S$725,0)) -> 700
A33: 10 | B33: =INDEX(Benchmarking!$A$4:$A$725,MATCH(LARGE(Benchmarking!$S$4:$S$725,10),Benchmarking!$S$4:$S$725,0)) -> Weyerhaeuser Co | C33: =INDEX(Benchmarking!$B$4:$B$725,MATCH(LARGE(Benchmarking!$S$4:$S$725,10),Benchmarking!$S$4:$S$725,0)) -> wy | D33: =INDEX(Benchmarking!$C$4:$C$725,MATCH(LARGE(Benchmarking!$S$4:$S$725,10),Benchmarking!$S$4:$S$725,0)) -> Real Estate | E33: =INDEX(Benchmarking!$D$4:$D$725,MATCH(LARGE(Benchmarking!$S$4:$S$725,10),Benchmarking!$S$4:$S$725,0)) -> 700
A34: 11 | B34: =INDEX(Benchmarking!$A$4:$A$725,MATCH(LARGE(Benchmarking!$S$4:$S$725,11),Benchmarking!$S$4:$S$725,0)) -> Lincoln National Corp | C34: =INDEX(Benchmarking!$B$4:$B$725,MATCH(LARGE(Benchmarking!$S$4:$S$725,11),Benchmarking!$S$4:$S$725,0)) -> lnc | D34: =INDEX(Benchmarking!$C$4:$C$725,MATCH(LARGE(Benchmarking!$S$4:$S$725,11),Benchmarking!$S$4:$S$725,0)) -> Insurance | E34: =INDEX(Benchmarking!$D$4:$D$725,MATCH(LARGE(Benchmarking!$S$4:$S$725,11),Benchmarking!$S$4:$S$725,0)) -> 700
A35: 12 | B35: =INDEX(Benchmarking!$A$4:$A$725,MATCH(LARGE(Benchmarking!$S$4:$S$725,12),Benchmarking!$S$4:$S$725,0)) -> Exelon Corp | C35: =INDEX(Benchmarking!$B$4:$B$725,MATCH(LARGE(Benchmarking!$S$4:$S$725,12),Benchmarking!$S$4:$S$725,0)) -> exc | D35: =INDEX(Benchmarking!$C$4:$C$725,MATCH(LARGE(Benchmarking!$S$4:$S$725,12),Benchmarking!$S$4:$S$725,0)) -> Utilities | E35: =INDEX(Benchmarking!$D$4:$D$725,MATCH(LARGE(Benchmarking!$S$4:$S$725,12),Benchmarking!$S$4:$S$725,0)) -> 694
A36: 13 | B36: =INDEX(Benchmarking!$A$4:$A$725,MATCH(LARGE(Benchmarking!$S$4:$S$725,13),Benchmarking!$S$4:$S$725,0)) -> Conocophillips | C36: =INDEX(Benchmarking!$B$4:$B$725,MATCH(LARGE(Benchmarking!$S$4:$S$725,13),Benchmarking!$S$4:$S$725,0)) -> cop | D36: =INDEX(Benchmarking!$C$4:$C$725,MATCH(LARGE(Benchmarking!$S$4:$S$725,13),Benchmarking!$S$4:$S$725,0)) -> Energy | E36: =INDEX(Benchmarking!$D$4:$D$725,MATCH(LARGE(Benchmarking!$S$4:$S$725,13),Benchmarking!$S$4:$S$725,0)) -> 687
A37: 14 | B37: =INDEX(Benchmarking!$A$4:$A$725,MATCH(LARGE(Benchmarking!$S$4:$S$725,14),Benchmarking!$S$4:$S$725,0)) -> Newmont Corporation | C37: =INDEX(Benchmarking!$B$4:$B$725,MATCH(LARGE(Benchmarking!$S$4:$S$725,14),Benchmarking!$S$4:$S$725,0)) -> nem | D37: =INDEX(Benchmarking!$C$4:$C$725,MATCH(LARGE(Benchmarking!$S$4:$S$725,14),Benchmarking!$S$4:$S$725,0)) -> Metals & Mining | E37: =INDEX(Benchmarking!$D$4:$D$725,MATCH(LARGE(Benchmarking!$S$4:$S$725,14),Benchmarking!$S$4:$S$725,0)) -> 675
A38: 15 | B38: =INDEX(Benchmarking!$A$4:$A$725,MATCH(LARGE(Benchmarking!$S$4:$S$725,15),Benchmarking!$S$4:$S$725,0)) -> Amazon.com Inc | C38: =INDEX(Benchmarking!$B$4:$B$725,MATCH(LARGE(Benchmarking!$S$4:$S$725,15),Benchmarking!$S$4:$S$725,0)) -> amzn | D38: =INDEX(Benchmarking!$C$4:$C$725,MATCH(LARGE(Benchmarking!$S$4:$S$725,15),Benchmarking!$S$4:$S$725,0)) -> Retail | E38: =INDEX(Benchmarking!$D$4:$D$725,MATCH(LARGE(Benchmarking!$S$4:$S$725,15),Benchmarking!$S$4:$S$725,0)) -> 668
A40: TOP 15 — SOCIAL RANKING
A41: Rank | B41: Company | C41: Ticker | D41: Industry | E41: Social Score
